<?xml version="1.0"?>
<robot name="TIAGo Steel" xmlns:xacro="http://ros.org/wiki/xacro">
  <link name="base_link">
    <visual>
      <origin xyz="0 0 0.06" rpy="3.1407962 0 0"/>
      <geometry>
        <cylinder radius="0.265" length="0.276"/>
      </geometry>
    </visual>
    <collision>
      <origin xyz="0 0 0.06" rpy="3.1407962 0 0"/>
      <geometry>
        <cylinder radius="0.265" length="0.276"/>
      </geometry>
    </collision>
    <visual>
      <origin xyz="-0.201 0.1062 0.28" rpy="3.1407962 0 0"/>
      <geometry>
        <cylinder radius="0.007" length="0.173"/>
      </geometry>
    </visual>
    <collision>
      <origin xyz="-0.201 0.1062 0.28" rpy="3.1407962 0 0"/>
      <geometry>
        <cylinder radius="0.007" length="0.173"/>
      </geometry>
    </collision>
    <visual>
      <origin xyz="-0.201 -0.1062 0.28" rpy="3.1407962 0 0"/>
      <geometry>
        <cylinder radius="0.007" length="0.173"/>
      </geometry>
    </visual>
    <collision>
      <origin xyz="-0.201 -0.1062 0.28" rpy="3.1407962 0 0"/>
      <geometry>
        <cylinder radius="0.007" length="0.173"/>
      </geometry>
    </collision>
  </link>
  <link name="Torso">
    <visual>
      <origin xyz="0 0 0.275" rpy="0 0 0"/>
      <geometry>
        <box size="0.18 0.2 0.55"/>
      </geometry>
    </visual>
    <collision>
      <origin xyz="0 0 0.275" rpy="0 0 0"/>
      <geometry>
        <box size="0.18 0.2 0.55"/>
      </geometry>
    </collision>
    <visual>
      <origin xyz="0.085 0 0.02" rpy="0 0 0"/>
      <geometry>
        <box size="0.4 0.254 0.04"/>
      </geometry>
    </visual>
    <collision>
      <origin xyz="0.085 0 0.02" rpy="0 0 0"/>
      <geometry>
        <box size="0.4 0.254 0.04"/>
      </geometry>
    </collision>
    <visual>
      <origin xyz="0.001 0 0.05" rpy="0 0 0"/>
      <geometry>
        <box size="0.233 0.26 0.12"/>
      </geometry>
    </visual>
    <collision>
      <origin xyz="0.001 0 0.05" rpy="0 0 0"/>
      <geometry>
        <box size="0.233 0.26 0.12"/>
      </geometry>
    </collision>
  </link>
  <joint name="base_link_Torso_joint" type="fixed">
    <parent link="base_link"/>
    <child link="Torso"/>
    <origin xyz="-0.054 0 0.193" rpy="0 0 0"/>
  </joint>
  <joint name="torso_lift_joint" type="prismatic">
    <parent link="Torso"/>
    <child link="torso_lift_link"/>
    <axis xyz="0 0 1"/>
    <origin xyz="0 0 0.6" rpy="0 0 0"/>
    <limit effort="2000" lower="0" upper="0.35" velocity="0.07"/>
  </joint>
  <link name="torso_lift_link">
    <visual>
      <origin xyz="0.164 0 -0.032" rpy="0 0 0"/>
      <geometry>
        <box size="0.15 0.138 0.074"/>
      </geometry>
    </visual>
    <collision>
      <origin xyz="0.164 0 -0.032" rpy="0 0 0"/>
      <geometry>
        <box size="0.15 0.138 0.074"/>
      </geometry>
    </collision>
    <visual>
      <origin xyz="0.1389 0 -0.0432" rpy="0 -0.43 0"/>
      <geometry>
        <box size="0.12 0.134 0.097"/>
      </geometry>
    </visual>
    <collision>
      <origin xyz="0.1389 0 -0.0432" rpy="0 -0.43 0"/>
      <geometry>
        <box size="0.12 0.134 0.097"/>
      </geometry>
    </collision>
    <visual>
      <origin xyz="-0.016 0 -0.05" rpy="0 0 0"/>
      <geometry>
        <box size="0.291 0.333 0.11"/>
      </geometry>
    </visual>
    <collision>
      <origin xyz="-0.016 0 -0.05" rpy="0 0 0"/>
      <geometry>
        <box size="0.291 0.333 0.11"/>
      </geometry>
    </collision>
    <visual>
      <origin xyz="0.003 0 -0.283" rpy="0 0 0"/>
      <geometry>
        <box size="0.228 0.263 0.358"/>
      </geometry>
    </visual>
    <collision>
      <origin xyz="0.003 0 -0.283" rpy="0 0 0"/>
      <geometry>
        <box size="0.228 0.263 0.358"/>
      </geometry>
    </collision>
  </link>
  <link name="TIAGo front arm_11367">
    <visual>
      <origin xyz="0.026 0.14 -0.232" rpy="0 0 1.5708"/>
      <geometry>
        <box size="0.042 0.094 0.094"/>
      </geometry>
    </visual>
    <collision>
      <origin xyz="0.026 0.14 -0.232" rpy="0 0 1.5708"/>
      <geometry>
        <box size="0.042 0.094 0.094"/>
      </geometry>
    </collision>
    <visual>
      <origin xyz="0.0256 0.1868 -0.2661" rpy="1.6887958e-05 -0.26184443 1.5707794"/>
      <geometry>
        <cylinder radius="0.053" length="0.016"/>
      </geometry>
    </visual>
    <collision>
      <origin xyz="0.0256 0.1868 -0.2661" rpy="1.6887958e-05 -0.26184443 1.5707794"/>
      <geometry>
        <cylinder radius="0.053" length="0.016"/>
      </geometry>
    </collision>
    <visual>
      <origin xyz="0.026 0.19 -0.221" rpy="-3.7000516e-06 0 0"/>
      <geometry>
        <cylinder radius="0.053" length="0.075"/>
      </geometry>
    </visual>
    <collision>
      <origin xyz="0.026 0.19 -0.221" rpy="-3.7000516e-06 0 0"/>
      <geometry>
        <cylinder radius="0.053" length="0.075"/>
      </geometry>
    </collision>
  </link>
  <joint name="torso_lift_link_TIAGo front arm_11367_joint" type="fixed">
    <parent link="torso_lift_link"/>
    <child link="TIAGo front arm_11367"/>
    <origin xyz="-0.037 0.0388 0.0224" rpy="0 0 -1.5708"/>
  </joint>
  <joint name="arm_1_joint" type="revolute">
    <parent link="TIAGo front arm_11367"/>
    <child link="arm_1_link"/>
    <axis xyz="0 0 1"/>
    <limit effort="43" lower="0.07" upper="2.68" velocity="1.95"/>
    <origin xyz="0.025 0.194 -0.16" rpy="0 0 0"/>
  </joint>
  <link name="arm_1_link">
    <visual>
      <origin xyz="0.0001 0 0.002" rpy="-3.141589 0 0"/>
      <geometry>
        <cylinder radius="0.0522" length="0.052"/>
      </geometry>
    </visual>
    <collision>
      <origin xyz="0.0001 0 0.002" rpy="-3.141589 0 0"/>
      <geometry>
        <cylinder radius="0.0522" length="0.052"/>
      </geometry>
    </collision>
    <visual>
      <origin xyz="0.0331 0.001 0.001" rpy="0 0 0"/>
      <geometry>
        <box size="0.08 0.1044 0.048"/>
      </geometry>
    </visual>
    <collision>
      <origin xyz="0.0331 0.001 0.001" rpy="0 0 0"/>
      <geometry>
        <box size="0.08 0.1044 0.048"/>
      </geometry>
    </collision>
    <visual>
      <origin xyz="0.0721 0.029 -0.023" rpy="0 0 0"/>
      <geometry>
        <box size="0.035 0.09 0.081"/>
      </geometry>
    </visual>
    <collision>
      <origin xyz="0.0721 0.029 -0.023" rpy="0 0 0"/>
      <geometry>
        <box size="0.035 0.09 0.081"/>
      </geometry>
    </collision>
    <visual>
      <origin xyz="0.1251 0.053 -0.042" rpy="1.5707963 0 0"/>
      <geometry>
        <cylinder radius="0.053" length="0.069"/>
      </geometry>
    </visual>
    <collision>
      <origin xyz="0.1251 0.053 -0.042" rpy="1.5707963 0 0"/>
      <geometry>
        <cylinder radius="0.053" length="0.069"/>
      </geometry>
    </collision>
  </link>
  <joint name="arm_2_joint" type="revolute">
    <parent link="arm_1_link"/>
    <child link="arm_2_link"/>
    <axis xyz="0 3.6732051e-06 1"/>
    <limit effort="43" lower="-1.5" upper="1.02" velocity="1.95"/>
    <origin xyz="0.1251 0.0195 -0.042" rpy="1.5708 0 0"/>
  </joint>
  <link name="arm_2_link">
    <visual>
      <origin xyz="0.056 5.5098077e-09 -0.0005" rpy="1.5707963 -2.7755576e-16 -1.5708"/>
      <geometry>
        <cylinder radius="0.052" length="0.048"/>
      </geometry>
    </visual>
    <collision>
      <origin xyz="0.056 5.5098077e-09 -0.0005" rpy="1.5707963 -2.7755576e-16 -1.5708"/>
      <geometry>
        <cylinder radius="0.052" length="0.048"/>
      </geometry>
    </collision>
    <visual>
      <origin xyz="0 5.5098077e-09 0.0295" rpy="-3.7000516e-06 0 0"/>
      <geometry>
        <cylinder radius="0.053" length="0.057"/>
      </geometry>
    </visual>
    <collision>
      <origin xyz="0 5.5098077e-09 0.0295" rpy="-3.7000516e-06 0 0"/>
      <geometry>
        <cylinder radius="0.053" length="0.057"/>
      </geometry>
    </collision>
  </link>
  <joint name="arm_3_joint" type="revolute">
    <parent link="arm_2_link"/>
    <child link="arm_3_link"/>
    <axis xyz="-7.801315e-05 -9.5201074e-05 1"/>
    <limit effort="26" lower="-3.46" upper="1.5" velocity="2.35"/>
    <origin xyz="0.0895 5.5098077e-09 -1.0118208e-14" rpy="-1.5708915 9.5201074e-05 1.5707183"/>
  </joint>
  <link name="arm_3_link">
    <visual>
      <origin xyz="-1.7943024e-07 -2.1896247e-07 -0.1037" rpy="-3.7000516e-06 0 0"/>
      <geometry>
        <cylinder radius="0.053" length="0.23"/>
      </geometry>
    </visual>
    <collision>
      <origin xyz="-1.7943024e-07 -2.1896247e-07 -0.1037" rpy="-3.7000516e-06 0 0"/>
      <geometry>
        <cylinder radius="0.053" length="0.23"/>
      </geometry>
    </collision>
    <visual>
      <origin xyz="-0.01690018 0.029999781 -0.2187" rpy="1.5707963 0 0"/>
      <geometry>
        <cylinder radius="0.056" length="0.056"/>
      </geometry>
    </visual>
    <collision>
      <origin xyz="-0.01690018 0.029999781 -0.2187" rpy="1.5707963 0 0"/>
      <geometry>
        <cylinder radius="0.056" length="0.056"/>
      </geometry>
    </collision>
  </link>
  <joint name="arm_4_joint" type="revolute">
    <parent link="arm_3_link"/>
    <child link="arm_4_link"/>
    <axis xyz="2.8276386e-06 -2.8276306e-06 1"/>
    <limit effort="26" lower="-0.32" upper="2.29" velocity="2.35"/>
    <origin xyz="-0.02000018 -0.027000219 -0.2197" rpy="2.356193 -1.5707923 2.356193"/>
  </joint>
  <link name="arm_4_link">
    <visual>
      <origin xyz="0 0.001 -0.002" rpy="-3.141589 0 0"/>
      <geometry>
        <cylinder radius="0.054" length="0.056"/>
      </geometry>
    </visual>
    <collision>
      <origin xyz="0 0.001 -0.002" rpy="-3.141589 0 0"/>
      <geometry>
        <cylinder radius="0.054" length="0.056"/>
      </geometry>
    </collision>
    <visual>
      <origin xyz="-0.093 0.019 0.027" rpy="1.5707963 -2.7755576e-16 -1.5708"/>
      <geometry>
        <cylinder radius="0.052" length="0.191"/>
      </geometry>
    </visual>
    <collision>
      <origin xyz="-0.093 0.019 0.027" rpy="1.5707963 -2.7755576e-16 -1.5708"/>
      <geometry>
        <cylinder radius="0.052" length="0.191"/>
      </geometry>
    </collision>
  </link>
  <joint name="arm_5_joint" type="revolute">
    <parent link="arm_4_link"/>
    <child link="arm_5_link"/>
    <axis xyz="3.6732051e-06 0 1"/>
    <limit effort="3" lower="-2.07" upper="2.07" velocity="1.95"/>
    <origin xyz="-0.162 0.02 0.027" rpy="3.1415927 -1.5707927 3.1415927"/>
  </joint>
  <link name="arm_5_link">
    <visual>
      <origin xyz="0 0 0.04" rpy="3.1407962 0 0"/>
      <geometry>
        <cylinder radius="0.063" length="0.062"/>
      </geometry>
    </visual>
    <collision>
      <origin xyz="0 0 0.04" rpy="3.1407962 0 0"/>
      <geometry>
        <cylinder radius="0.063" length="0.062"/>
      </geometry>
    </collision>
    <visual>
      <origin xyz="0 0 0.099" rpy="3.1407962 0 0"/>
      <geometry>
        <cylinder radius="0.057" length="0.06"/>
      </geometry>
    </visual>
    <collision>
      <origin xyz="0 0 0.099" rpy="3.1407962 0 0"/>
      <geometry>
        <cylinder radius="0.057" length="0.06"/>
      </geometry>
    </collision>
    <visual>
      <origin xyz="0 0 0.156" rpy="3.1407962 0 0"/>
      <geometry>
        <cylinder radius="0.053" length="0.06"/>
      </geometry>
    </visual>
    <collision>
      <origin xyz="0 0 0.156" rpy="3.1407962 0 0"/>
      <geometry>
        <cylinder radius="0.053" length="0.06"/>
      </geometry>
    </collision>
  </link>
  <joint name="arm_6_joint" type="revolute">
    <parent link="arm_5_link"/>
    <child link="arm_6_link"/>
    <axis xyz="2.8276386e-06 -2.8276306e-06 1"/>
    <limit effort="6.6" lower="-1.39" upper="1.39" velocity="1.76"/>
    <origin xyz="0 0 0.15" rpy="2.356193 -1.5707923 2.356193"/>
  </joint>
  <link name="arm_6_link">
    <visual>
      <origin xyz="0.0409 0 0" rpy="1.5707963 -2.7755576e-16 -1.5708"/>
      <geometry>
        <cylinder radius="0.0226" length="0.013"/>
      </geometry>
    </visual>
    <collision>
      <origin xyz="0.0409 0 0" rpy="1.5707963 -2.7755576e-16 -1.5708"/>
      <geometry>
        <cylinder radius="0.0226" length="0.013"/>
      </geometry>
    </collision>
  </link>
  <joint name="arm_7_joint" type="revolute">
    <parent link="arm_6_link"/>
    <child link="arm_7_link"/>
    <axis xyz="-2.8276306e-06 2.8276386e-06 1"/>
    <limit effort="6.6" lower="-2.07" upper="2.07" velocity="1.76"/>
    <origin xyz="0 0 0" rpy="1.5707991 -2.8276386e-06 1.5707991"/>
  </joint>
  <link name="arm_7_link">
    <visual>
      <origin xyz="-1.5551969e-07 1.5552013e-07 0.055" rpy="-3.141589 0 0"/>
      <geometry>
        <cylinder radius="0.0225" length="0.0157"/>
      </geometry>
    </visual>
    <collision>
      <origin xyz="-1.5551969e-07 1.5552013e-07 0.055" rpy="-3.141589 0 0"/>
      <geometry>
        <cylinder radius="0.0225" length="0.0157"/>
      </geometry>
    </collision>
  </link>
</robot>
