<?xml version="1.0"?>
<robot name="TIAGo Steel" xmlns:xacro="http://ros.org/wiki/xacro">
  <link name="base_link">
    <visual>
      <origin xyz="0 0 0.06" rpy="0 0 0"/>
      <geometry>
        <cylinder radius="0.265" length="0.276"/>
      </geometry>
    </visual>
    <collision>
      <origin xyz="0 0 0.06" rpy="0 0 0"/>
      <geometry>
        <cylinder radius="0.265" length="0.276"/>
      </geometry>
    </collision>
    <visual>
      <origin xyz="-0.201 0.1062 0.28" rpy="0 0 0"/>
      <geometry>
        <cylinder radius="0.007" length="0.173"/>
      </geometry>
    </visual>
    <collision>
      <origin xyz="-0.201 0.1062 0.28" rpy="0 0 0"/>
      <geometry>
        <cylinder radius="0.007" length="0.173"/>
      </geometry>
    </collision>
    <visual>
      <origin xyz="-0.201 -0.1062 0.28" rpy="0 0 0"/>
      <geometry>
        <cylinder radius="0.007" length="0.173"/>
      </geometry>
    </visual>
    <collision>
      <origin xyz="-0.201 -0.1062 0.28" rpy="0 0 0"/>
      <geometry>
        <cylinder radius="0.007" length="0.173"/>
      </geometry>
    </collision>
  </link>
  <joint name="CASTER_WHEEL_BACK_LEFT_JOINT" type="continuous">
    <parent link="base_link"/>
    <child link="caster_back_left_1_link"/>
    <axis xyz="-0.000001 0 1"/>
    <origin xyz="-0.1735 0.102 -0.0335" rpy="0 0.000001 -0.08667"/>
  </joint>
  <link name="caster_back_left_1_link">
    <visual>
      <origin xyz="-0.003001 0.000001 -0.02183" rpy="0 0 0"/>
      <geometry>
        <box size="0.036 0.032 0.04"/>
      </geometry>
    </visual>
    <collision>
      <origin xyz="-0.003001 0.000001 -0.02183" rpy="0 0 0"/>
      <geometry>
        <box size="0.036 0.032 0.04"/>
      </geometry>
    </collision>
  </link>
  <joint name="SMALL_WHEEL_JOINT" type="continuous">
    <parent link="caster_back_left_1_link"/>
    <child link="caster_back_left_2_link"/>
    <axis xyz="0 -0.000004 1"/>
    <origin xyz="-0.016001 0.000001 -0.03983" rpy="-1.5708 0.044384 0"/>
  </joint>
  <link name="caster_back_left_2_link">
    <visual>
      <origin xyz="0 0 0" rpy="0 0 0"/>
      <geometry>
        <cylinder radius="0.025" length="0.015"/>
      </geometry>
    </visual>
    <collision>
      <origin xyz="0 0 0" rpy="0 0 0"/>
      <geometry>
        <cylinder radius="0.025" length="0.015"/>
      </geometry>
    </collision>
  </link>
  <joint name="CASTER_WHEEL_BACK_RIGHT_JOINT" type="continuous">
    <parent link="base_link"/>
    <child link="caster_back_right_1_link"/>
    <axis xyz="-0.000003 0 1"/>
    <origin xyz="-0.1735 -0.102 -0.0335" rpy="0 0.000003 -0.120633"/>
  </joint>
  <link name="caster_back_right_1_link">
    <visual>
      <origin xyz="-0.003004 0.000002 -0.021547" rpy="0 0 0"/>
      <geometry>
        <box size="0.036 0.032 0.04"/>
      </geometry>
    </visual>
    <collision>
      <origin xyz="-0.003004 0.000002 -0.021547" rpy="0 0 0"/>
      <geometry>
        <box size="0.036 0.032 0.04"/>
      </geometry>
    </collision>
  </link>
  <joint name="SMALL_WHEEL_JOINT_0" type="continuous">
    <parent link="caster_back_right_1_link"/>
    <child link="caster_back_right_2_link"/>
    <axis xyz="0 -0.000004 1"/>
    <origin xyz="-0.016004 0.000002 -0.039547" rpy="-1.5708 0.035051 0"/>
  </joint>
  <link name="caster_back_right_2_link">
    <visual>
      <origin xyz="0 0 0" rpy="0 0 0"/>
      <geometry>
        <cylinder radius="0.025" length="0.015"/>
      </geometry>
    </visual>
    <collision>
      <origin xyz="0 0 0" rpy="0 0 0"/>
      <geometry>
        <cylinder radius="0.025" length="0.015"/>
      </geometry>
    </collision>
  </link>
  <joint name="CASTER_WHEEL_FRONT_LEFT_JOINT" type="continuous">
    <parent link="base_link"/>
    <child link="caster_front_left_1_link"/>
    <axis xyz="-0.000003 0 1"/>
    <origin xyz="0.1695 0.102 -0.0335" rpy="0 0.000003 -0.14025"/>
  </joint>
  <link name="caster_front_left_1_link">
    <visual>
      <origin xyz="-0.003004 0.000002 -0.02154" rpy="0 0 0"/>
      <geometry>
        <box size="0.036 0.032 0.04"/>
      </geometry>
    </visual>
    <collision>
      <origin xyz="-0.003004 0.000002 -0.02154" rpy="0 0 0"/>
      <geometry>
        <box size="0.036 0.032 0.04"/>
      </geometry>
    </collision>
  </link>
  <joint name="SMALL_WHEEL_JOINT_1" type="continuous">
    <parent link="caster_front_left_1_link"/>
    <child link="caster_front_left_2_link"/>
    <axis xyz="0 -0.000004 1"/>
    <origin xyz="-0.016004 0.000002 -0.03954" rpy="-1.5708 0.046738 0"/>
  </joint>
  <link name="caster_front_left_2_link">
    <visual>
      <origin xyz="0 0 0" rpy="0 0 0"/>
      <geometry>
        <cylinder radius="0.025" length="0.015"/>
      </geometry>
    </visual>
    <collision>
      <origin xyz="0 0 0" rpy="0 0 0"/>
      <geometry>
        <cylinder radius="0.025" length="0.015"/>
      </geometry>
    </collision>
  </link>
  <joint name="CASTER_WHEEL_FRONT_RIGHT_JOINT" type="continuous">
    <parent link="base_link"/>
    <child link="caster_front_right_1_link"/>
    <axis xyz="-0.000005 0 1"/>
    <origin xyz="0.1695 -0.102 -0.0335" rpy="0 0.000005 -0.173648"/>
  </joint>
  <link name="caster_front_right_1_link">
    <visual>
      <origin xyz="-0.003007 0.000003 -0.021257" rpy="0 0 0"/>
      <geometry>
        <box size="0.036 0.032 0.04"/>
      </geometry>
    </visual>
    <collision>
      <origin xyz="-0.003007 0.000003 -0.021257" rpy="0 0 0"/>
      <geometry>
        <box size="0.036 0.032 0.04"/>
      </geometry>
    </collision>
  </link>
  <joint name="SMALL_WHEEL_JOINT_2" type="continuous">
    <parent link="caster_front_right_1_link"/>
    <child link="caster_front_right_2_link"/>
    <axis xyz="0 -0.000004 1"/>
    <origin xyz="-0.016007 0.000003 -0.039257" rpy="-1.5708 0.037623 0"/>
  </joint>
  <link name="caster_front_right_2_link">
    <visual>
      <origin xyz="0 0 0" rpy="0 0 0"/>
      <geometry>
        <cylinder radius="0.025" length="0.015"/>
      </geometry>
    </visual>
    <collision>
      <origin xyz="0 0 0" rpy="0 0 0"/>
      <geometry>
        <cylinder radius="0.025" length="0.015"/>
      </geometry>
    </collision>
  </link>
  <joint name="wheel_left_joint" type="continuous">
    <parent link="base_link"/>
    <child link="wheel_left_link"/>
    <axis xyz="0 -0.000004 -1"/>
    <limit effort="10" velocity="10.1523"/>
    <origin xyz="0 0.2022 0" rpy="1.570801 0.015623 0"/>
  </joint>
  <link name="wheel_left_link">
    <visual>
      <origin xyz="-0.000002 0.000055 0.000193" rpy="0 0 0"/>
      <geometry>
        <cylinder radius="0.0985" length="0.04"/>
      </geometry>
    </visual>
    <collision>
      <origin xyz="-0.000002 0.000055 0.000193" rpy="0 0 0"/>
      <geometry>
        <cylinder radius="0.0985" length="0.04"/>
      </geometry>
    </collision>
  </link>
  <joint name="wheel_right_joint" type="continuous">
    <parent link="base_link"/>
    <child link="wheel_right_link"/>
    <axis xyz="0 -0.000005 -1"/>
    <limit effort="10" velocity="10.1523"/>
    <origin xyz="-0.000002 -0.202145 0.000193" rpy="1.570801 0.015525 0"/>
  </joint>
  <link name="wheel_right_link">
    <visual>
      <origin xyz="-0.000007 0.000291 -0.000214" rpy="0 0 0"/>
      <geometry>
        <cylinder radius="0.0985" length="0.04"/>
      </geometry>
    </visual>
    <collision>
      <origin xyz="-0.000007 0.000291 -0.000214" rpy="0 0 0"/>
      <geometry>
        <cylinder radius="0.0985" length="0.04"/>
      </geometry>
    </collision>
  </link>
  <link name="base_sonar_01_link">
  </link>
  <joint name="base_link_base_sonar_01_link_joint" type="fixed">
    <parent link="base_link"/>
    <child link="base_sonar_01_link"/>
    <origin xyz="-0.183007 -0.182709 0.172786" rpy="0 0 -2.356185"/>
  </joint>
  <link name="base_sonar_02_link">
  </link>
  <joint name="base_link_base_sonar_02_link_joint" type="fixed">
    <parent link="base_link"/>
    <child link="base_sonar_02_link"/>
    <origin xyz="-0.259 0 0.173" rpy="0 0 -3.141585"/>
  </joint>
  <link name="base_sonar_03_link">
  </link>
  <joint name="base_link_base_sonar_03_link_joint" type="fixed">
    <parent link="base_link"/>
    <child link="base_sonar_03_link"/>
    <origin xyz="-0.183 0.183 0.173" rpy="0 0 2.3562"/>
  </joint>
  <link name="base_cover_link">
    <visual>
      <origin xyz="0 0 0.043" rpy="0 0 0"/>
      <geometry>
        <cylinder radius="0.272" length="0.086"/>
      </geometry>
    </visual>
    <collision>
      <origin xyz="0 0 0.043" rpy="0 0 0"/>
      <geometry>
        <cylinder radius="0.272" length="0.086"/>
      </geometry>
    </collision>
  </link>
  <joint name="base_link_base_cover_link_joint" type="fixed">
    <parent link="base_link"/>
    <child link="base_cover_link"/>
    <origin xyz="0 0 0.029988" rpy="0 0 0"/>
  </joint>
  <link name="base_footprint">
  </link>
  <joint name="base_link_base_footprint_joint" type="fixed">
    <parent link="base_link"/>
    <child link="base_footprint"/>
    <origin xyz="0 0 -0.095" rpy="0 0 0"/>
  </joint>
  <link name="gyro">
  </link>
  <joint name="base_link_gyro_joint" type="fixed">
    <parent link="base_link"/>
    <child link="gyro"/>
    <origin xyz="0 0 0" rpy="0 0 0"/>
  </joint>
  <link name="inertial unit">
  </link>
  <joint name="base_link_inertial unit_joint" type="fixed">
    <parent link="base_link"/>
    <child link="inertial unit"/>
    <origin xyz="0 0 0" rpy="0 0 0"/>
  </joint>
  <link name="accelerometer">
  </link>
  <joint name="base_link_accelerometer_joint" type="fixed">
    <parent link="base_link"/>
    <child link="accelerometer"/>
    <origin xyz="0 0 0" rpy="0 0 0"/>
  </joint>
  <link name="onboard_lidar_1">
    <visual>
      <origin xyz="0 0 -0.018" rpy="1.570741 0.000118 -1.570741"/>
      <geometry>
        <box size="0.05 0.07 0.05"/>
      </geometry>
    </visual>
    <collision>
      <origin xyz="0 0 -0.018" rpy="1.570741 0.000118 -1.570741"/>
      <geometry>
        <box size="0.05 0.07 0.05"/>
      </geometry>
    </collision>
  </link>
  <joint name="base_link_onboard_lidar_1_joint" type="fixed">
    <parent link="base_link"/>
    <child link="onboard_lidar_1"/>
    <origin xyz="0.202 0 1.046" rpy="0 0 0"/>
  </joint>
  <link name="gps(1)">
  </link>
  <joint name="base_link_gps(1)_joint" type="fixed">
    <parent link="base_link"/>
    <child link="gps(1)"/>
    <origin xyz="0.202 0 -0.004" rpy="0 0 0"/>
  </joint>
  <link name="compass(1)">
  </link>
  <joint name="base_link_compass(1)_joint" type="fixed">
    <parent link="base_link"/>
    <child link="compass(1)"/>
    <origin xyz="0.202 0 -0.004" rpy="0 0 0"/>
  </joint>
  <link name="plastic crate(1)">
    <visual>
      <origin xyz="0 0.0035 0" rpy="0 0 0"/>
      <geometry>
        <box size="0.6 0.01 0.4"/>
      </geometry>
    </visual>
    <collision>
      <origin xyz="0 0.0035 0" rpy="0 0 0"/>
      <geometry>
        <box size="0.6 0.01 0.4"/>
      </geometry>
    </collision>
    <visual>
      <origin xyz="0.2895 0.1035 0" rpy="0 0 0"/>
      <geometry>
        <box size="0.021 0.193 0.372"/>
      </geometry>
    </visual>
    <collision>
      <origin xyz="0.2895 0.1035 0" rpy="0 0 0"/>
      <geometry>
        <box size="0.021 0.193 0.372"/>
      </geometry>
    </collision>
    <visual>
      <origin xyz="-0.2895 0.1035 0" rpy="0 0 0"/>
      <geometry>
        <box size="0.021 0.193 0.372"/>
      </geometry>
    </visual>
    <collision>
      <origin xyz="-0.2895 0.1035 0" rpy="0 0 0"/>
      <geometry>
        <box size="0.021 0.193 0.372"/>
      </geometry>
    </collision>
    <visual>
      <origin xyz="0 0.1035 0.193" rpy="0 0 0"/>
      <geometry>
        <box size="0.6 0.193 0.021"/>
      </geometry>
    </visual>
    <collision>
      <origin xyz="0 0.1035 0.193" rpy="0 0 0"/>
      <geometry>
        <box size="0.6 0.193 0.021"/>
      </geometry>
    </collision>
    <visual>
      <origin xyz="0 0.1035 -0.193" rpy="0 0 0"/>
      <geometry>
        <box size="0.6 0.193 0.021"/>
      </geometry>
    </visual>
    <collision>
      <origin xyz="0 0.1035 -0.193" rpy="0 0 0"/>
      <geometry>
        <box size="0.6 0.193 0.021"/>
      </geometry>
    </collision>
  </link>
  <joint name="base_link_plastic crate(1)_joint" type="fixed">
    <parent link="base_link"/>
    <child link="plastic crate(1)"/>
    <origin xyz="0.272 -0.010001 0.236" rpy="1.570798 -0.000005 1.570798"/>
  </joint>
  <link name="Hokuyo URG-04LX-UG01">
    <visual>
      <origin xyz="0 0 -0.018" rpy="1.570741 0.000118 -1.570741"/>
      <geometry>
        <box size="0.05 0.07 0.05"/>
      </geometry>
    </visual>
    <collision>
      <origin xyz="0 0 -0.018" rpy="1.570741 0.000118 -1.570741"/>
      <geometry>
        <box size="0.05 0.07 0.05"/>
      </geometry>
    </collision>
  </link>
  <joint name="base_link_Hokuyo URG-04LX-UG01_joint" type="fixed">
    <parent link="base_link"/>
    <child link="Hokuyo URG-04LX-UG01"/>
    <origin xyz="0.202 0 -0.004" rpy="0 0 0"/>
  </joint>
  <link name="gps">
  </link>
  <joint name="base_link_gps_joint" type="fixed">
    <parent link="base_link"/>
    <child link="gps"/>
    <origin xyz="0.202 0 -0.004" rpy="0 0 0"/>
  </joint>
  <link name="compass">
  </link>
  <joint name="base_link_compass_joint" type="fixed">
    <parent link="base_link"/>
    <child link="compass"/>
    <origin xyz="0.202 0 -0.004" rpy="0 0 0"/>
  </joint>
  <link name="plastic crate">
    <visual>
      <origin xyz="0 0.0035 0" rpy="0 0 0"/>
      <geometry>
        <box size="0.6 0.01 0.4"/>
      </geometry>
    </visual>
    <collision>
      <origin xyz="0 0.0035 0" rpy="0 0 0"/>
      <geometry>
        <box size="0.6 0.01 0.4"/>
      </geometry>
    </collision>
    <visual>
      <origin xyz="0.2895 0.1035 0" rpy="0 0 0"/>
      <geometry>
        <box size="0.021 0.193 0.372"/>
      </geometry>
    </visual>
    <collision>
      <origin xyz="0.2895 0.1035 0" rpy="0 0 0"/>
      <geometry>
        <box size="0.021 0.193 0.372"/>
      </geometry>
    </collision>
    <visual>
      <origin xyz="-0.2895 0.1035 0" rpy="0 0 0"/>
      <geometry>
        <box size="0.021 0.193 0.372"/>
      </geometry>
    </visual>
    <collision>
      <origin xyz="-0.2895 0.1035 0" rpy="0 0 0"/>
      <geometry>
        <box size="0.021 0.193 0.372"/>
      </geometry>
    </collision>
    <visual>
      <origin xyz="0 0.1035 0.193" rpy="0 0 0"/>
      <geometry>
        <box size="0.6 0.193 0.021"/>
      </geometry>
    </visual>
    <collision>
      <origin xyz="0 0.1035 0.193" rpy="0 0 0"/>
      <geometry>
        <box size="0.6 0.193 0.021"/>
      </geometry>
    </collision>
    <visual>
      <origin xyz="0 0.1035 -0.193" rpy="0 0 0"/>
      <geometry>
        <box size="0.6 0.193 0.021"/>
      </geometry>
    </visual>
    <collision>
      <origin xyz="0 0.1035 -0.193" rpy="0 0 0"/>
      <geometry>
        <box size="0.6 0.193 0.021"/>
      </geometry>
    </collision>
  </link>
  <joint name="base_link_plastic crate_joint" type="fixed">
    <parent link="base_link"/>
    <child link="plastic crate"/>
    <origin xyz="0.272 -0.010001 0.236" rpy="1.570798 -0.000005 1.570798"/>
  </joint>
  <link name="Torso">
    <visual>
      <origin xyz="0 0 0.275" rpy="0 0 0"/>
      <geometry>
        <box size="0.18 0.2 0.55"/>
      </geometry>
    </visual>
    <collision>
      <origin xyz="0 0 0.275" rpy="0 0 0"/>
      <geometry>
        <box size="0.18 0.2 0.55"/>
      </geometry>
    </collision>
    <visual>
      <origin xyz="0.085 0 0.02" rpy="0 0 0"/>
      <geometry>
        <box size="0.4 0.254 0.04"/>
      </geometry>
    </visual>
    <collision>
      <origin xyz="0.085 0 0.02" rpy="0 0 0"/>
      <geometry>
        <box size="0.4 0.254 0.04"/>
      </geometry>
    </collision>
    <visual>
      <origin xyz="0.001 0 0.05" rpy="0 0 0"/>
      <geometry>
        <box size="0.233 0.26 0.12"/>
      </geometry>
    </visual>
    <collision>
      <origin xyz="0.001 0 0.05" rpy="0 0 0"/>
      <geometry>
        <box size="0.233 0.26 0.12"/>
      </geometry>
    </collision>
  </link>
  <joint name="base_link_Torso_joint" type="fixed">
    <parent link="base_link"/>
    <child link="Torso"/>
    <origin xyz="-0.054 0 0.193" rpy="0 0 0"/>
  </joint>
  <joint name="torso_lift_joint" type="prismatic">
    <parent link="Torso"/>
    <child link="torso_lift_link"/>
    <axis xyz="-0.000028 0.00006 1"/>
    <origin xyz="0.000025 -0.00005 0.600001" rpy="0.00006 0.000028 0"/>
    <limit effort="2000" lower="-0.000253603" upper="0.35" velocity="0.07"/>
  </joint>
  <link name="torso_lift_link">
    <visual>
      <origin xyz="0.164 0 -0.032254" rpy="0 0 0"/>
      <geometry>
        <box size="0.15 0.138 0.074"/>
      </geometry>
    </visual>
    <collision>
      <origin xyz="0.164 0 -0.032254" rpy="0 0 0"/>
      <geometry>
        <box size="0.15 0.138 0.074"/>
      </geometry>
    </collision>
    <visual>
      <origin xyz="0.1389 0 -0.043454" rpy="0 -0.43 0"/>
      <geometry>
        <box size="0.12 0.134 0.097"/>
      </geometry>
    </visual>
    <collision>
      <origin xyz="0.1389 0 -0.043454" rpy="0 -0.43 0"/>
      <geometry>
        <box size="0.12 0.134 0.097"/>
      </geometry>
    </collision>
    <visual>
      <origin xyz="-0.016 0 -0.050254" rpy="0 0 0"/>
      <geometry>
        <box size="0.291 0.333 0.11"/>
      </geometry>
    </visual>
    <collision>
      <origin xyz="-0.016 0 -0.050254" rpy="0 0 0"/>
      <geometry>
        <box size="0.291 0.333 0.11"/>
      </geometry>
    </collision>
    <visual>
      <origin xyz="0.003 0 -0.283254" rpy="0 0 0"/>
      <geometry>
        <box size="0.228 0.263 0.358"/>
      </geometry>
    </visual>
    <collision>
      <origin xyz="0.003 0 -0.283254" rpy="0 0 0"/>
      <geometry>
        <box size="0.228 0.263 0.358"/>
      </geometry>
    </collision>
  </link>
  <joint name="head_1_joint" type="revolute">
    <parent link="torso_lift_link"/>
    <child link="head_1_link"/>
    <axis xyz="0 -0.000004 1"/>
    <limit effort="5.197" lower="-1.24" upper="1.24" velocity="3"/>
    <origin xyz="0.182 0 -0.000254" rpy="-0.000004 0 -1.570796"/>
  </joint>
  <link name="head_1_link">
    <visual>
      <origin xyz="0.010002 0.000026 0.096981" rpy="-1.5708 0 0"/>
      <geometry>
        <cylinder radius="0.082" length="0.09"/>
      </geometry>
    </visual>
    <collision>
      <origin xyz="0.010002 0.000026 0.096981" rpy="-1.5708 0 0"/>
      <geometry>
        <cylinder radius="0.082" length="0.09"/>
      </geometry>
    </collision>
    <visual>
      <origin xyz="-0.004998 0.000026 0.004981" rpy="0 0 0"/>
      <geometry>
        <box size="0.103 0.088 0.103"/>
      </geometry>
    </visual>
    <collision>
      <origin xyz="-0.004998 0.000026 0.004981" rpy="0 0 0"/>
      <geometry>
        <box size="0.103 0.088 0.103"/>
      </geometry>
    </collision>
  </link>
  <joint name="head_2_joint" type="revolute">
    <parent link="head_1_link"/>
    <child link="head_2_link"/>
    <axis xyz="0 0.000004 1"/>
    <limit effort="2.77" lower="-0.98" upper="0.79" velocity="3"/>
    <origin xyz="0.005002 0.000026 0.097981" rpy="1.5708 0 0"/>
  </joint>
  <link name="head_2_link">
    <visual>
      <origin xyz="-0.009 0.02659 -0.000001" rpy="0 0 -0.7"/>
      <geometry>
        <box size="0.092 0.132 0.26"/>
      </geometry>
    </visual>
    <collision>
      <origin xyz="-0.009 0.02659 -0.000001" rpy="0 0 -0.7"/>
      <geometry>
        <box size="0.092 0.132 0.26"/>
      </geometry>
    </collision>
    <visual>
      <origin xyz="0.008 -0.03901 -0.000001" rpy="0 0 -1.5708"/>
      <geometry>
        <cylinder radius="0.03" length="0.132"/>
      </geometry>
    </visual>
    <collision>
      <origin xyz="0.008 -0.03901 -0.000001" rpy="0 0 -1.5708"/>
      <geometry>
        <cylinder radius="0.03" length="0.132"/>
      </geometry>
    </collision>
    <visual>
      <origin xyz="0.054 0.03999 -0.000001" rpy="0 0 0"/>
      <geometry>
        <box size="0.111 0.13 0.16"/>
      </geometry>
    </visual>
    <collision>
      <origin xyz="0.054 0.03999 -0.000001" rpy="0 0 0"/>
      <geometry>
        <box size="0.111 0.13 0.16"/>
      </geometry>
    </collision>
    <visual>
      <origin xyz="0.053 0.03599 -0.068001" rpy="3.141593 -1.570793 3.141593"/>
      <geometry>
        <cylinder radius="0.0667" length="0.111"/>
      </geometry>
    </visual>
    <collision>
      <origin xyz="0.053 0.03599 -0.068001" rpy="3.141593 -1.570793 3.141593"/>
      <geometry>
        <cylinder radius="0.0667" length="0.111"/>
      </geometry>
    </collision>
    <visual>
      <origin xyz="0.053 0.03599 0.067999" rpy="3.141593 -1.570793 3.141593"/>
      <geometry>
        <cylinder radius="0.0667" length="0.111"/>
      </geometry>
    </visual>
    <collision>
      <origin xyz="0.053 0.03599 0.067999" rpy="3.141593 -1.570793 3.141593"/>
      <geometry>
        <cylinder radius="0.0667" length="0.111"/>
      </geometry>
    </collision>
  </link>
  <link name="display">
  </link>
  <joint name="head_2_link_display_joint" type="fixed">
    <parent link="head_2_link"/>
    <child link="display"/>
    <origin xyz="0.107 0.06019 -0.000001" rpy="0 0 0"/>
  </joint>
  <link name="camera">
  </link>
  <joint name="head_2_link_camera_joint" type="fixed">
    <parent link="head_2_link"/>
    <child link="camera"/>
    <origin xyz="0.107 0.0802 0" rpy="-3.141592 0 -1.570796"/>
  </joint>
  <link name="TIAGo front arm">
    <visual>
      <origin xyz="0.026 0.14 -0.232" rpy="0 0 1.5708"/>
      <geometry>
        <box size="0.042 0.094 0.094"/>
      </geometry>
    </visual>
    <collision>
      <origin xyz="0.026 0.14 -0.232" rpy="0 0 1.5708"/>
      <geometry>
        <box size="0.042 0.094 0.094"/>
      </geometry>
    </collision>
    <visual>
      <origin xyz="0.0256 0.1868 -0.2661" rpy="0.261799 0 0"/>
      <geometry>
        <cylinder radius="0.053" length="0.016"/>
      </geometry>
    </visual>
    <collision>
      <origin xyz="0.0256 0.1868 -0.2661" rpy="0.261799 0 0"/>
      <geometry>
        <cylinder radius="0.053" length="0.016"/>
      </geometry>
    </collision>
    <visual>
      <origin xyz="0.026 0.19 -0.221" rpy="0 0 -1.5708"/>
      <geometry>
        <cylinder radius="0.053" length="0.075"/>
      </geometry>
    </visual>
    <collision>
      <origin xyz="0.026 0.19 -0.221" rpy="0 0 -1.5708"/>
      <geometry>
        <cylinder radius="0.053" length="0.075"/>
      </geometry>
    </collision>
  </link>
  <joint name="torso_lift_link_TIAGo front arm_joint" type="fixed">
    <parent link="torso_lift_link"/>
    <child link="TIAGo front arm"/>
    <origin xyz="-0.037 0.0388 0.0224" rpy="0 0 -1.5708"/>
  </joint>
  <joint name="arm_1_joint" type="revolute">
    <parent link="TIAGo front arm"/>
    <child link="TIAGo front arm_3"/>
    <axis xyz="0 0 1"/>
    <limit effort="43" lower="0.0698809" upper="2.68" velocity="1.95"/>
    <origin xyz="0.025 0.194 -0.16" rpy="0 0 0.008881"/>
  </joint>
  <link name="TIAGo front arm_3">
    <visual>
      <origin xyz="0.0001 -0.000001 0.002" rpy="0 0 1.5708"/>
      <geometry>
        <cylinder radius="0.0522" length="0.052"/>
      </geometry>
    </visual>
    <collision>
      <origin xyz="0.0001 -0.000001 0.002" rpy="0 0 1.5708"/>
      <geometry>
        <cylinder radius="0.0522" length="0.052"/>
      </geometry>
    </collision>
    <visual>
      <origin xyz="0.0331 0.000999 0.001" rpy="0 0 0"/>
      <geometry>
        <box size="0.08 0.1044 0.048"/>
      </geometry>
    </visual>
    <collision>
      <origin xyz="0.0331 0.000999 0.001" rpy="0 0 0"/>
      <geometry>
        <box size="0.08 0.1044 0.048"/>
      </geometry>
    </collision>
    <visual>
      <origin xyz="0.0721 0.028999 -0.023" rpy="0 0 0"/>
      <geometry>
        <box size="0.035 0.09 0.081"/>
      </geometry>
    </visual>
    <collision>
      <origin xyz="0.0721 0.028999 -0.023" rpy="0 0 0"/>
      <geometry>
        <box size="0.035 0.09 0.081"/>
      </geometry>
    </collision>
    <visual>
      <origin xyz="0.1251 0.052999 -0.042" rpy="1.5708 0 0"/>
      <geometry>
        <cylinder radius="0.053" length="0.069"/>
      </geometry>
    </visual>
    <collision>
      <origin xyz="0.1251 0.052999 -0.042" rpy="1.5708 0 0"/>
      <geometry>
        <cylinder radius="0.053" length="0.069"/>
      </geometry>
    </collision>
  </link>
  <joint name="arm_2_joint" type="revolute">
    <parent link="TIAGo front arm_3"/>
    <child link="arm_2_link"/>
    <axis xyz="0 0.000004 1"/>
    <limit effort="43" lower="-1.5" upper="1.02" velocity="1.95"/>
    <origin xyz="0.1251 0.019499 -0.042" rpy="1.5708 0.000023 0"/>
  </joint>
  <link name="arm_2_link">
    <visual>
      <origin xyz="0.056 0 -0.0005" rpy="3.141593 -1.570793 3.141593"/>
      <geometry>
        <cylinder radius="0.052" length="0.048"/>
      </geometry>
    </visual>
    <collision>
      <origin xyz="0.056 0 -0.0005" rpy="3.141593 -1.570793 3.141593"/>
      <geometry>
        <cylinder radius="0.052" length="0.048"/>
      </geometry>
    </collision>
    <visual>
      <origin xyz="0 0 0.0295" rpy="0 0 -1.5708"/>
      <geometry>
        <cylinder radius="0.053" length="0.057"/>
      </geometry>
    </visual>
    <collision>
      <origin xyz="0 0 0.0295" rpy="0 0 -1.5708"/>
      <geometry>
        <cylinder radius="0.053" length="0.057"/>
      </geometry>
    </collision>
  </link>
  <joint name="arm_3_joint" type="revolute">
    <parent link="arm_2_link"/>
    <child link="arm_3_link"/>
    <axis xyz="-0.000078 -0.000095 1"/>
    <limit effort="26" lower="-3.46" upper="1.5" velocity="2.35"/>
    <origin xyz="0.0895 0 0" rpy="-1.570892 0.000124 1.570718"/>
  </joint>
  <link name="arm_3_link">
    <visual>
      <origin xyz="0 0 -0.1037" rpy="0 0 -1.5708"/>
      <geometry>
        <cylinder radius="0.053" length="0.23"/>
      </geometry>
    </visual>
    <collision>
      <origin xyz="0 0 -0.1037" rpy="0 0 -1.5708"/>
      <geometry>
        <cylinder radius="0.053" length="0.23"/>
      </geometry>
    </collision>
    <visual>
      <origin xyz="-0.0169 0.03 -0.2187" rpy="1.5708 0 0"/>
      <geometry>
        <cylinder radius="0.056" length="0.056"/>
      </geometry>
    </visual>
    <collision>
      <origin xyz="-0.0169 0.03 -0.2187" rpy="1.5708 0 0"/>
      <geometry>
        <cylinder radius="0.056" length="0.056"/>
      </geometry>
    </collision>
  </link>
  <joint name="arm_4_joint" type="revolute">
    <parent link="arm_3_link"/>
    <child link="arm_4_link"/>
    <axis xyz="0.000004 0.000003 1"/>
    <limit effort="26" lower="-0.32" upper="2.29" velocity="2.35"/>
    <origin xyz="-0.02 -0.027 -0.2197" rpy="1.570909 -1.531801 3.141483"/>
  </joint>
  <link name="arm_4_link">
    <visual>
      <origin xyz="-0.000025 0.000922 -0.002" rpy="0 0 1.5708"/>
      <geometry>
        <cylinder radius="0.054" length="0.056"/>
      </geometry>
    </visual>
    <collision>
      <origin xyz="-0.000025 0.000922 -0.002" rpy="0 0 1.5708"/>
      <geometry>
        <cylinder radius="0.054" length="0.056"/>
      </geometry>
    </collision>
    <visual>
      <origin xyz="-0.093025 0.018922 0.027" rpy="3.141593 1.570793 3.141593"/>
      <geometry>
        <cylinder radius="0.052" length="0.191"/>
      </geometry>
    </visual>
    <collision>
      <origin xyz="-0.093025 0.018922 0.027" rpy="3.141593 1.570793 3.141593"/>
      <geometry>
        <cylinder radius="0.052" length="0.191"/>
      </geometry>
    </collision>
  </link>
  <joint name="arm_5_joint" type="revolute">
    <parent link="arm_4_link"/>
    <child link="arm_5_link"/>
    <axis xyz="0.000004 0 1"/>
    <limit effort="3" lower="-2.07" upper="2.07" velocity="1.95"/>
    <origin xyz="-0.162025 0.019922 0.027" rpy="-1.570797 -0.250796 1.5708"/>
  </joint>
  <link name="arm_5_link">
    <visual>
      <origin xyz="0 0 0.04" rpy="0 0 1.57"/>
      <geometry>
        <cylinder radius="0.063" length="0.062"/>
      </geometry>
    </visual>
    <collision>
      <origin xyz="0 0 0.04" rpy="0 0 1.57"/>
      <geometry>
        <cylinder radius="0.063" length="0.062"/>
      </geometry>
    </collision>
    <visual>
      <origin xyz="0 0 0.099" rpy="0 0 1.57"/>
      <geometry>
        <cylinder radius="0.057" length="0.06"/>
      </geometry>
    </visual>
    <collision>
      <origin xyz="0 0 0.099" rpy="0 0 1.57"/>
      <geometry>
        <cylinder radius="0.057" length="0.06"/>
      </geometry>
    </collision>
    <visual>
      <origin xyz="0 0 0.156" rpy="0 0 1.57"/>
      <geometry>
        <cylinder radius="0.053" length="0.06"/>
      </geometry>
    </visual>
    <collision>
      <origin xyz="0 0 0.156" rpy="0 0 1.57"/>
      <geometry>
        <cylinder radius="0.053" length="0.06"/>
      </geometry>
    </collision>
  </link>
  <joint name="arm_6_joint" type="revolute">
    <parent link="arm_5_link"/>
    <child link="arm_6_link"/>
    <axis xyz="0.000003 -0.000003 1"/>
    <limit effort="6.6" lower="-1.39" upper="1.39" velocity="1.76"/>
    <origin xyz="0 0 0.15" rpy="2.269806 -1.570792 2.44258"/>
  </joint>
  <link name="arm_6_link">
    <visual>
      <origin xyz="0.0409 0 0" rpy="3.141593 1.570793 3.141593"/>
      <geometry>
        <cylinder radius="0.0226" length="0.013"/>
      </geometry>
    </visual>
    <collision>
      <origin xyz="0.0409 0 0" rpy="3.141593 1.570793 3.141593"/>
      <geometry>
        <cylinder radius="0.0226" length="0.013"/>
      </geometry>
    </collision>
  </link>
  <joint name="arm_7_joint" type="revolute">
    <parent link="arm_6_link"/>
    <child link="arm_7_link"/>
    <axis xyz="-0.000003 0.000003 1"/>
    <limit effort="6.6" lower="-2.07" upper="2.07" velocity="1.76"/>
    <origin xyz="0 0 0" rpy="1.570782 -1.410003 1.570814"/>
  </joint>
  <link name="arm_7_link">
    <visual>
      <origin xyz="0 0 0.055" rpy="0 0 1.5708"/>
      <geometry>
        <cylinder radius="0.0225" length="0.0157"/>
      </geometry>
    </visual>
    <collision>
      <origin xyz="0 0 0.055" rpy="0 0 1.5708"/>
      <geometry>
        <cylinder radius="0.0225" length="0.0157"/>
      </geometry>
    </collision>
  </link>
  <link name="wrist_ft_tool_link">
    <visual>
      <origin xyz="0 0 0.055" rpy="0 1.57 0"/>
      <geometry>
        <cylinder radius="0.0253" length="0.011"/>
      </geometry>
    </visual>
    <collision>
      <origin xyz="0 0 0.055" rpy="0 1.57 0"/>
      <geometry>
        <cylinder radius="0.0253" length="0.011"/>
      </geometry>
    </collision>
  </link>
  <joint name="arm_7_link_wrist_ft_tool_link_joint" type="fixed">
    <parent link="arm_7_link"/>
    <child link="wrist_ft_tool_link"/>
    <origin xyz="0 0 0.067725" rpy="2.356193 -1.570792 2.356193"/>
  </joint>
  <link name="front">
    <visual>
      <origin xyz="0 0 0" rpy="0 0 0"/>
      <geometry>
        <cylinder radius="0.0227" length="0.028"/>
      </geometry>
    </visual>
    <collision>
      <origin xyz="0 0 0" rpy="0 0 0"/>
      <geometry>
        <cylinder radius="0.0227" length="0.028"/>
      </geometry>
    </collision>
    <visual>
      <origin xyz="0.029 -0.01834 -0.046" rpy="0 0 0.59"/>
      <geometry>
        <box size="0.04 0.0217 0.105"/>
      </geometry>
    </visual>
    <collision>
      <origin xyz="0.029 -0.01834 -0.046" rpy="0 0 0.59"/>
      <geometry>
        <box size="0.04 0.0217 0.105"/>
      </geometry>
    </collision>
    <visual>
      <origin xyz="-0.029 0.01834 -0.046" rpy="0 0 0.59"/>
      <geometry>
        <box size="0.04 0.0217 0.105"/>
      </geometry>
    </visual>
    <collision>
      <origin xyz="-0.029 0.01834 -0.046" rpy="0 0 0.59"/>
      <geometry>
        <box size="0.04 0.0217 0.105"/>
      </geometry>
    </collision>
    <visual>
      <origin xyz="0.0172 0.0109 -0.046" rpy="3.141593 -1.570793 3.141593"/>
      <geometry>
        <box size="0.106 0.056 0.071"/>
      </geometry>
    </visual>
    <collision>
      <origin xyz="0.0172 0.0109 -0.046" rpy="3.141593 -1.570793 3.141593"/>
      <geometry>
        <box size="0.106 0.056 0.071"/>
      </geometry>
    </collision>
    <visual>
      <origin xyz="-0.0172 -0.0109 -0.046" rpy="3.141593 -1.570793 3.141593"/>
      <geometry>
        <box size="0.106 0.056 0.071"/>
      </geometry>
    </visual>
    <collision>
      <origin xyz="-0.0172 -0.0109 -0.046" rpy="3.141593 -1.570793 3.141593"/>
      <geometry>
        <box size="0.106 0.056 0.071"/>
      </geometry>
    </collision>
  </link>
  <joint name="wrist_ft_tool_link_front_joint" type="fixed">
    <parent link="wrist_ft_tool_link"/>
    <child link="front"/>
    <origin xyz="0.016 0 0" rpy="-2.356193 1.570792 0.785393"/>
  </joint>
  <joint name="gripper_right_finger_joint" type="prismatic">
    <parent link="front"/>
    <child link="gripper_right_finger_link"/>
    <axis xyz="1 -0.000005 0"/>
    <origin xyz="0 0 0" rpy="0 0 0.000005"/>
    <limit effort="16" lower="0" upper="0.045" velocity="0.05"/>
  </joint>
  <link name="gripper_right_finger_link">
    <visual>
      <origin xyz="0.012365 0 -0.1741" rpy="0 0 0"/>
      <geometry>
        <box size="0.0076 0.05091 0.08982"/>
      </geometry>
    </visual>
    <collision>
      <origin xyz="0.012365 0 -0.1741" rpy="0 0 0"/>
      <geometry>
        <box size="0.0076 0.05091 0.08982"/>
      </geometry>
    </collision>
    <visual>
      <origin xyz="0.013265 0.0153 -0.1208" rpy="0 0 0"/>
      <geometry>
        <box size="0.0055 0.0295 0.018"/>
      </geometry>
    </visual>
    <collision>
      <origin xyz="0.013265 0.0153 -0.1208" rpy="0 0 0"/>
      <geometry>
        <box size="0.0055 0.0295 0.018"/>
      </geometry>
    </collision>
    <visual>
      <origin xyz="-0.000135 0.0156 -0.1048" rpy="0 0 0"/>
      <geometry>
        <box size="0.03213 0.02959 0.01487"/>
      </geometry>
    </visual>
    <collision>
      <origin xyz="-0.000135 0.0156 -0.1048" rpy="0 0 0"/>
      <geometry>
        <box size="0.03213 0.02959 0.01487"/>
      </geometry>
    </collision>
  </link>
  <joint name="gripper_left_finger_joint" type="prismatic">
    <parent link="front"/>
    <child link="gripper_left_finger_link"/>
    <axis xyz="1 0.000093 0"/>
    <origin xyz="0.008365 0 0" rpy="0 0 3.1415"/>
    <limit effort="16" lower="0" upper="0.045" velocity="0.05"/>
  </joint>
  <link name="gripper_left_finger_link">
    <visual>
      <origin xyz="0.012382 0.000001 -0.1741" rpy="0 0 0"/>
      <geometry>
        <box size="0.0076 0.05091 0.08982"/>
      </geometry>
    </visual>
    <collision>
      <origin xyz="0.012382 0.000001 -0.1741" rpy="0 0 0"/>
      <geometry>
        <box size="0.0076 0.05091 0.08982"/>
      </geometry>
    </collision>
    <visual>
      <origin xyz="0.013282 0.015301 -0.1208" rpy="0 0 0"/>
      <geometry>
        <box size="0.0055 0.0295 0.018"/>
      </geometry>
    </visual>
    <collision>
      <origin xyz="0.013282 0.015301 -0.1208" rpy="0 0 0"/>
      <geometry>
        <box size="0.0055 0.0295 0.018"/>
      </geometry>
    </collision>
    <visual>
      <origin xyz="-0.000118 0.015601 -0.1048" rpy="0 0 0"/>
      <geometry>
        <box size="0.03213 0.02959 0.01487"/>
      </geometry>
    </visual>
    <collision>
      <origin xyz="-0.000118 0.015601 -0.1048" rpy="0 0 0"/>
      <geometry>
        <box size="0.03213 0.02959 0.01487"/>
      </geometry>
    </collision>
  </link>
  <link name="cap screw(19)">
  </link>
  <joint name="front_cap screw(19)_joint" type="fixed">
    <parent link="front"/>
    <child link="cap screw(19)"/>
    <origin xyz="0.049882 -0.002899 -0.0004" rpy="3.14159 0 0"/>
  </joint>
  <link name="cap screw(18)">
  </link>
  <joint name="front_cap screw(18)_joint" type="fixed">
    <parent link="front"/>
    <child link="cap screw(18)"/>
    <origin xyz="-0.0415 0.0029 -0.0004" rpy="3.14159 0 0"/>
  </joint>
  <link name="cap screw(17)">
  </link>
  <joint name="front_cap screw(17)_joint" type="fixed">
    <parent link="front"/>
    <child link="cap screw(17)"/>
    <origin xyz="0.0433 0.0315 0.0026" rpy="3.14159 0 0"/>
  </joint>
  <link name="cap screw(16)">
  </link>
  <joint name="front_cap screw(16)_joint" type="fixed">
    <parent link="front"/>
    <child link="cap screw(16)"/>
    <origin xyz="-0.0433 -0.0315 0.0026" rpy="3.14159 0 0"/>
  </joint>
  <link name="cap screw(15)">
  </link>
  <joint name="front_cap screw(15)_joint" type="fixed">
    <parent link="front"/>
    <child link="cap screw(15)"/>
    <origin xyz="0 0.033 0.0026" rpy="3.14159 0 0"/>
  </joint>
  <link name="cap screw(14)">
  </link>
  <joint name="front_cap screw(14)_joint" type="fixed">
    <parent link="front"/>
    <child link="cap screw(14)"/>
    <origin xyz="0 -0.033 0.0026" rpy="3.14159 0 0"/>
  </joint>
  <link name="cap screw(13)">
  </link>
  <joint name="front_cap screw(13)_joint" type="fixed">
    <parent link="front"/>
    <child link="cap screw(13)"/>
    <origin xyz="0.0426 -0.0094 -0.09448" rpy="0 0 0"/>
  </joint>
  <link name="cap screw(12)">
  </link>
  <joint name="front_cap screw(12)_joint" type="fixed">
    <parent link="front"/>
    <child link="cap screw(12)"/>
    <origin xyz="-0.0425 0.0094 -0.0945" rpy="0 0 0"/>
  </joint>
  <link name="cap screw(11)">
  </link>
  <joint name="front_cap screw(11)_joint" type="fixed">
    <parent link="front"/>
    <child link="cap screw(11)"/>
    <origin xyz="-0.0477 -0.008 -0.0108" rpy="3.141593 1.570793 3.141593"/>
  </joint>
  <link name="cap screw(10)">
  </link>
  <joint name="front_cap screw(10)_joint" type="fixed">
    <parent link="front"/>
    <child link="cap screw(10)"/>
    <origin xyz="-0.0477 -0.008 -0.043" rpy="3.141593 1.570793 3.141593"/>
  </joint>
  <link name="cap screw(9)">
  </link>
  <joint name="front_cap screw(9)_joint" type="fixed">
    <parent link="front"/>
    <child link="cap screw(9)"/>
    <origin xyz="-0.0477 -0.008 -0.075" rpy="3.141593 1.570793 3.141593"/>
  </joint>
  <link name="cap screw(8)">
  </link>
  <joint name="front_cap screw(8)_joint" type="fixed">
    <parent link="front"/>
    <child link="cap screw(8)"/>
    <origin xyz="-0.0477 0.008 -0.075" rpy="3.141593 1.570793 3.141593"/>
  </joint>
  <link name="cap screw(7)">
  </link>
  <joint name="front_cap screw(7)_joint" type="fixed">
    <parent link="front"/>
    <child link="cap screw(7)"/>
    <origin xyz="-0.0477 0.008 -0.043" rpy="3.141593 1.570793 3.141593"/>
  </joint>
  <link name="cap screw(6)">
  </link>
  <joint name="front_cap screw(6)_joint" type="fixed">
    <parent link="front"/>
    <child link="cap screw(6)"/>
    <origin xyz="-0.0477 0.008 -0.0108" rpy="3.141593 1.570793 3.141593"/>
  </joint>
  <link name="cap screw(5)">
  </link>
  <joint name="front_cap screw(5)_joint" type="fixed">
    <parent link="front"/>
    <child link="cap screw(5)"/>
    <origin xyz="0.0477 -0.008 -0.0108" rpy="3.141593 -1.570793 3.141593"/>
  </joint>
  <link name="cap screw(4)">
  </link>
  <joint name="front_cap screw(4)_joint" type="fixed">
    <parent link="front"/>
    <child link="cap screw(4)"/>
    <origin xyz="0.0477 -0.008 -0.043" rpy="3.141593 -1.570793 3.141593"/>
  </joint>
  <link name="cap screw(3)">
  </link>
  <joint name="front_cap screw(3)_joint" type="fixed">
    <parent link="front"/>
    <child link="cap screw(3)"/>
    <origin xyz="0.0477 -0.008 -0.075" rpy="3.141593 -1.570793 3.141593"/>
  </joint>
  <link name="cap screw(2)">
  </link>
  <joint name="front_cap screw(2)_joint" type="fixed">
    <parent link="front"/>
    <child link="cap screw(2)"/>
    <origin xyz="0.0477 0.008 -0.075" rpy="3.141593 -1.570793 3.141593"/>
  </joint>
  <link name="cap screw(1)">
  </link>
  <joint name="front_cap screw(1)_joint" type="fixed">
    <parent link="front"/>
    <child link="cap screw(1)"/>
    <origin xyz="0.0477 0.008 -0.043" rpy="3.141593 -1.570793 3.141593"/>
  </joint>
  <link name="cap screw">
  </link>
  <joint name="front_cap screw_joint" type="fixed">
    <parent link="front"/>
    <child link="cap screw"/>
    <origin xyz="0.0477 0.008 -0.0108" rpy="3.141593 -1.570793 3.141593"/>
  </joint>
</robot>
